<?xml version="1.0"?>
<sdf version='1.7'>
  <model name='jinu_manipulator'>

    <joint name='world_joint' type='fixed'>
      <child>link1</child>
      <parent>world</parent>
      <axis>
        <xyz>0 0 0</xyz>
        <limit>
          <lower>-1e+16</lower>
          <upper>1e+16</upper>
        </limit>
        <dynamics>
          <spring_reference>0</spring_reference>
          <spring_stiffness>0</spring_stiffness>
        </dynamics>
        <use_parent_model_frame>1</use_parent_model_frame>
      </axis>      
    </joint>

    <link name='link1'>
      <inertial>
        <pose>0.000336 0.000198 0.027277 0 -0 0</pose>
        <mass>0.52654</mass>
        <inertia>
          <ixx>0.0002675</ixx>
          <ixy>-2.0087e-06</ixy>
          <ixz>2.9573e-06</ixz>
          <iyy>0.00026005</iyy>
          <iyz>-4.6189e-07</iyz>
          <izz>0.00041434</izz>
        </inertia>
      </inertial>
      <collision name='link1_collision'>
        <pose>0 0 0 0 -0 0</pose>
        <geometry>
          <mesh>
            <scale>1 1 1</scale>
            <uri>model://jinu_manipulator_description/meshes/collada/base_link.dae</uri>
          </mesh>
        </geometry>
      </collision>
      <visual name='link1_visual'>
        <pose>0 0 0 0 -0 0</pose>
        <geometry>
          <mesh>
            <scale>1 1 1</scale>
            <uri>model://jinu_manipulator_description/meshes/collada/base_link.dae</uri>
          </mesh>
        </geometry>
      </visual>
    </link>
    <joint name='joint1' type='revolute'>
      <pose relative_to='link1'>0 0 0 0 -0 0</pose>
      <parent>link1</parent>
      <child>link2</child>
      <axis>
        <xyz>0 0 1</xyz>
          <dynamics>
	           <friction>0.5</friction>
	           <damping>0.5</damping>
	        </dynamics>
<!--
        <limit>
          <lower>-3.14159</lower>
          <upper>3.14159</upper>
          <effort>1</effort>
          <velocity>4.8</velocity>
        </limit>
-->
        <dynamics>
          <spring_reference>0</spring_reference>
          <spring_stiffness>0</spring_stiffness>
        </dynamics>
      </axis>
    </joint>
    <link name='link2'>
      <pose relative_to='joint1'>0 0 0 0 -0 0</pose>
      <inertial>
        <pose>-0.000159 0.02935 0.094506 0 -0 0</pose>
        <mass>0.52932</mass>
        <inertia>
          <ixx>0.000257</ixx>
          <ixy>-5.943e-07</ixy>
          <ixz>-1.8105e-07</ixz>
          <iyy>0.00038939</iyy>
          <iyz>-1.5019e-06</iyz>
          <izz>0.00029988</izz>
        </inertia>
      </inertial>
      <collision name='link2_collision'>
        <pose>0 0 0 0 -0 0</pose>
        <geometry>
          <mesh>
            <scale>1 1 1</scale>
            <uri>model://jinu_manipulator_description/meshes/collada/shoulder_link.dae</uri>
          </mesh>
        </geometry>
      </collision>
      <visual name='link2_visual'>
        <pose>0 0 0 0 -0 0</pose>
        <geometry>
          <mesh>
            <scale>1 1 1</scale>
            <uri>model://jinu_manipulator_description/meshes/collada/shoulder_link.dae</uri>
          </mesh>
        </geometry>
      </visual>
    </link>
    <joint name='joint2' type='revolute'>
      <pose relative_to='link2'>0 0 0.101 0 3.141592 0</pose>
      <parent>link2</parent>
      <child>link3</child>
      <axis>
        <xyz>0 1 0</xyz>
          <dynamics>
	           <friction>0.2</friction>
	           <damping>0.2</damping>
	        </dynamics>
<!--
        <limit>
          <lower>-3.141592</lower>
          <upper>0</upper>
          <effort>1</effort>
          <velocity>4.8</velocity>
        </limit>
-->
        <dynamics>
          <spring_reference>0</spring_reference>
          <spring_stiffness>0</spring_stiffness>
        </dynamics>
      </axis>
    </joint>
    <link name='link3'>
      <pose relative_to='joint2'>0 0 0 0 -0 0</pose>
      <inertial>
        <pose>-0.043569 -0.018054 0.000233 0 -0 0</pose>
        <mass>0.67459</mass>
        <inertia>
          <ixx>0.00024014</ixx>
          <ixy>-1.0253e-06</ixy>
          <ixz>4.9927e-07</ixz>
          <iyy>0.0018727</iyy>
          <iyz>1.6438e-08</iyz>
          <izz>0.0017182</izz>
        </inertia>
      </inertial>
      <collision name='link3_collision'>
        <pose>0 0 0 0 -0 0</pose>
        <geometry>
          <mesh>
            <scale>1 1 1</scale>
            <uri>model://jinu_manipulator_description/meshes/collada/arm_link.dae</uri>
          </mesh>
        </geometry>
      </collision>
      <visual name='link3_visual'>
        <pose>0 0 0 0 -0 0</pose>
        <geometry>
          <mesh>
            <scale>1 1 1</scale>
            <uri>model://jinu_manipulator_description/meshes/collada/arm_link.dae</uri>
          </mesh>
        </geometry>
      </visual>
    </link>
    <joint name='joint3' type='revolute'>
      <pose relative_to='link3'>-0.2495 0 0 0 -2.84019 0</pose>
      <parent>link3</parent>
      <child>link4</child>
      <axis>
        <xyz>0 1 0</xyz>
          <dynamics>
	           <friction>0.25</friction>
	           <damping>0.25</damping>
	        </dynamics>
<!--
        <limit>
          <lower>-0.3005</lower>
          <upper>2.84109</upper>
          <effort>1</effort>
          <velocity>4.8</velocity>
        </limit>
-->
        <dynamics>
          <spring_reference>0</spring_reference>
          <spring_stiffness>0</spring_stiffness>
        </dynamics>
      </axis>
    </joint>
    <link name='link4'>
      <pose relative_to='joint3'>0 0 0 0 -0 0</pose>
      <inertial>
        <pose>0.13512 -0.001481 0.051429 0 -0 0</pose>
        <mass>0.43335</mass>
        <inertia>
          <ixx>0.00022562</ixx>
          <ixy>3.1358e-07</ixy>
          <ixz>-0.00026116</ixz>
          <iyy>0.0013039</iyy>
          <iyz>4.3754e-08</iyz>
          <izz>0.0011013</izz>
        </inertia>
      </inertial>
      <collision name='link4_collision'>
        <pose>0 0 0 0 -0 0</pose>
        <geometry>
          <mesh>
            <scale>1 1 1</scale>
            <uri>model://jinu_manipulator_description/meshes/collada/elbow_link.dae</uri>
          </mesh>
        </geometry>
      </collision>
      <visual name='link4_visual'>
        <pose>0 0 0 0 -0 0</pose>
        <geometry>
          <mesh>
            <scale>1 1 1</scale>
            <uri>model://jinu_manipulator_description/meshes/collada/elbow_link.dae</uri>
          </mesh>
        </geometry>
      </visual>
    </link>
    <joint name='joint4' type='revolute'>
      <pose relative_to='link4'>0.2388 0 0.074 0 -0.3005 0</pose>
      <parent>link4</parent>
      <child>link5</child>
      <axis>
        <xyz>0 1 0</xyz>
          <dynamics>
	           <friction>0.2</friction>
	           <damping>0.2</damping>
	        </dynamics>
<!--
        <limit>
          <lower>-1.79071</lower>
          <upper>1.79071</upper>
          <effort>1</effort>
          <velocity>4.8</velocity>
        </limit>
-->
        <dynamics>
          <spring_reference>0</spring_reference>
          <spring_stiffness>0</spring_stiffness>
        </dynamics>
      </axis>
    </joint>
    <link name='link5'>
      <pose relative_to='joint4'>0 0 0 0 -0 0</pose>
      <inertial>
        <pose>0.046587 0.000935 5e-06 0 -0 0</pose>
        <mass>0.13384</mass>
        <inertia>
          <ixx>3.6374e-05</ixx>
          <ixy>1.1852e-06</ixy>
          <ixz>4.7596e-10</ixz>
          <iyy>2.2671e-05</iyy>
          <iyz>-2.5504e-07</iyz>
          <izz>2.207e-05</izz>
        </inertia>
      </inertial>
      <collision name='link5_collision'>
        <pose>0 0 0 0 -0 0</pose>
        <geometry>
          <mesh>
            <scale>1 1 1</scale>
            <uri>model://jinu_manipulator_description/meshes/collada/forearm_link.dae</uri>
          </mesh>
        </geometry>
      </collision>
      <visual name='link5_visual'>
        <pose>0 0 0 0 -0 0</pose>
        <geometry>
          <mesh>
            <scale>1 1 1</scale>
            <uri>model://jinu_manipulator_description/meshes/collada/forearm_link.dae</uri>
          </mesh>
        </geometry>
      </visual>
    </link>
    <joint name='joint5' type='revolute'>
      <pose relative_to='link5'>0 0 0 0 -0 0</pose>
      <parent>link5</parent>
      <child>link6</child>
      <axis>
        <xyz>1 0 0</xyz>
          <dynamics>
	           <friction>0.2</friction>
	           <damping>0.2</damping>
	        </dynamics>
<!--
        <limit>
          <lower>-3.14159</lower>
          <upper>3.14159</upper>
          <effort>1</effort>
          <velocity>4.8</velocity>
        </limit>
-->
        <dynamics>
          <spring_reference>0</spring_reference>
          <spring_stiffness>0</spring_stiffness>
        </dynamics>
      </axis>
    </joint>
    <link name='link6'>
      <pose relative_to='joint5'>0 0 0 0 -0 0</pose>
      <inertial>
        <pose>0.046587 0.000935 5e-06 0 -0 0</pose>
        <mass>0.13384</mass>
        <inertia>
          <ixx>3.6374e-05</ixx>
          <ixy>1.1852e-06</ixy>
          <ixz>4.7596e-10</ixz>
          <iyy>2.2671e-05</iyy>
          <iyz>-2.5504e-07</iyz>
          <izz>2.207e-05</izz>
        </inertia>
      </inertial>
      <collision name='link6_collision'>
        <pose>0 0 0 0 -0 0</pose>
        <geometry>
          <mesh>
            <scale>1 1 1</scale>
            <uri>model://jinu_manipulator_description/meshes/collada/wrist_link.dae</uri>
          </mesh>
        </geometry>
      </collision>
      <visual name='link6_visual'>
        <pose>0 0 0 0 -0 0</pose>
        <geometry>
          <mesh>
            <scale>1 1 1</scale>
            <uri>model://jinu_manipulator_description/meshes/collada/wrist_link.dae</uri>
          </mesh>
        </geometry>
      </visual>
    </link>
    <joint name='joint6' type='revolute'>
      <pose relative_to='link6'>0.0965 0 0 0 -0 0</pose>
      <parent>link6</parent>
      <child>link7</child>
      <axis>
        <xyz>0 0 1</xyz>
          <dynamics>
	           <friction>0.2</friction>
	           <damping>0.2</damping>
	        </dynamics>
<!--
        <limit>
          <lower>-3.14159</lower>
          <upper>3.14159</upper>
          <effort>1</effort>
          <velocity>4.8</velocity>
        </limit>
-->
        <dynamics>
          <spring_reference>0</spring_reference>
          <spring_stiffness>0</spring_stiffness>
        </dynamics>
      </axis>
    </joint>
    <link name='link7'>
      <pose relative_to='joint6'>0 0 0 0 -0 0</pose>
      <inertial>
        <pose>0.048577 0.000518 0.022163 0 -0 0</pose>
        <mass>0.12395</mass>
        <inertia>
          <ixx>7.2028e-05</ixx>
          <ixy>4.5222e-08</ixy>
          <ixz>8.2578e-07</ixz>
          <iyy>2.6906e-05</iyy>
          <iyz>1.8737e-07</iyz>
          <izz>6.267e-05</izz>
        </inertia>
      </inertial>
      <collision name='link7_collision'>
        <pose>0 0 0 0 -0 0</pose>
        <geometry>
          <mesh>
            <scale>1 1 1</scale>
            <uri>model://jinu_manipulator_description/meshes/collada/ee.dae</uri>
          </mesh>
        </geometry>
      </collision>
      <visual name='link7_visual'>
        <pose>0 0 0 0 -0 0</pose>
        <geometry>
          <mesh>
            <scale>1 1 1</scale>
            <uri>model://jinu_manipulator_description/meshes/collada/ee.dae</uri>
          </mesh>
        </geometry>
      </visual>
    </link>
    <joint name='gripper' type='prismatic'>
      <pose relative_to='link7'>0.0655 -0.053826 0 0 -0 0</pose>
      <parent>link7</parent>
      <child>gripper_link</child>
      <axis>
        <xyz>0 1 0</xyz>
        	<dynamics>
	           <friction>0.2</friction>
	           <damping>0.2</damping>
	        </dynamics>
<!--
        <limit>
          <lower>0</lower>
          <upper>0</upper>
          <effort>0</effort>
          <velocity>0</velocity>
        </limit>
-->
        <dynamics>
          <spring_reference>0</spring_reference>
          <spring_stiffness>0</spring_stiffness>
        </dynamics>
      </axis>
    </joint>
    <link name='gripper_link'>
      <pose relative_to='gripper'>0 0 0 0 -0 0</pose>
      <inertial>
        <pose>0.022425 -0.001366 -0.0001 0 -0 0</pose>
        <mass>0.016158</mass>
        <inertia>
          <ixx>1.7408e-06</ixx>
          <ixy>-1.0523e-06</ixy>
          <ixz>-1.1613e-10</ixz>
          <iyy>6.2034e-06</iyy>
          <iyz>-7.1721e-12</iyz>
          <izz>7.2381e-06</izz>
        </inertia>
      </inertial>
      <collision name='gripper_link_collision'>
        <pose>0 0 0 0 -0 0</pose>
        <geometry>
          <mesh>
            <scale>1 1 1</scale>
            <uri>model://jinu_manipulator_description/meshes/collada/gripperR.dae</uri>
          </mesh>
        </geometry>
      </collision>
      <visual name='gripper_link_visual'>
        <pose>0 0 0 0 -0 0</pose>
        <geometry>
          <mesh>
            <scale>1 1 1</scale>
            <uri>model://jinu_manipulator_description/meshes/collada/gripperR.dae</uri>
          </mesh>
        </geometry>
      </visual>
    </link>
    <joint name='gripper_sub' type='prismatic'>
      <pose relative_to='link7'>0.0655 0.053826 0 0 -0 0</pose>
      <parent>link7</parent>
      <child>gripper_link_sub</child>
      <axis>
        <xyz>0 -1 0</xyz>
        	<dynamics>
	           <friction>0.2</friction>
	           <damping>0.2</damping>
	        </dynamics>
<!--
        <limit>
          <lower>0</lower>
          <upper>0</upper>
          <effort>0</effort>
          <velocity>0</velocity>
        </limit>
-->
        <dynamics>
          <spring_reference>0</spring_reference>
          <spring_stiffness>0</spring_stiffness>
        </dynamics>
      </axis>
    </joint>
    <link name='gripper_link_sub'>
      <pose relative_to='gripper_sub'>0 0 0 0 -0 0</pose>
      <inertial>
        <pose>0.022425 0.001366 -0.0001 0 -0 0</pose>
        <mass>0.016158</mass>
        <inertia>
          <ixx>1.7408e-06</ixx>
          <ixy>1.0523e-06</ixy>
          <ixz>-1.1695e-10</ixz>
          <iyy>6.2034e-06</iyy>
          <iyz>6.5231e-12</iyz>
          <izz>7.2381e-06</izz>
        </inertia>
      </inertial>
      <collision name='gripper_link_sub_collision'>
        <pose>0 0 0 0 -0 0</pose>
        <geometry>
          <mesh>
            <scale>1 1 1</scale>
            <uri>model://jinu_manipulator_description/meshes/collada/gripperL.dae</uri>
          </mesh>
        </geometry>
      </collision>
      <visual name='gripper_link_sub_visual'>
        <pose>0 0 0 0 -0 0</pose>
        <geometry>
          <mesh>
            <scale>1 1 1</scale>
            <uri>model://jinu_manipulator_description/meshes/collada/gripperL.dae</uri>
          </mesh>
        </geometry>
      </visual>
    </link>
  </model>
</sdf>
