<?xml version="1.0" ?>
<!-- =================================================================================== -->
<!-- |    This document was autogenerated by xacro from jinu_manipulator.urdf.xacro    | -->
<!-- |    EDITING THIS FILE BY HAND IS NOT RECOMMENDED                                 | -->
<!-- =================================================================================== -->
<!-- Jinu_Manipulator Chain -->
<robot name="jinu_manipulator">
  <!-- Link 1 -->
  <link name="link1">
    <visual>
      <origin rpy="0 0 0" xyz="0 0 0"/>
      <geometry>
        <mesh filename="package://jinu_manipulator_description/meshes/collada/base_link.dae"/>
      </geometry>
      <material name="grey"/>
    </visual>
    <collision>
      <origin rpy="0 0 0" xyz="0 0 0"/>
      <geometry>
        <mesh filename="package://jinu_manipulator_description/meshes/collada/base_link.dae"/>
      </geometry>
    </collision>
    <inertial>
      <origin rpy="0 0 0" xyz="0.00033638 0.000198 0.027277"/>
      <mass value="0.52654"/>
      <inertia ixx="0.0002675" ixy="-2.0087E-06" ixz="2.9573E-06" iyy="0.00026005" iyz="-4.6189E-07" izz="0.00041434"/>
    </inertial>
  </link>
  <!-- Joint 1 -->
  <joint name="joint1" type="revolute">
    <parent link="link1"/>
    <child link="link2"/>
    <origin rpy="0 0 0" xyz="0 0 0"/>
    <axis xyz="0 0 1"/>
    <limit effort="1" lower="-3.141592653589793" upper="3.141592653589793" velocity="4.8"/>
  </joint>
  <!--  Link 2 -->
  <link name="link2">
    <visual>
      <origin rpy="0 0 0" xyz="0 0 0"/>
      <geometry>
        <mesh filename="package://jinu_manipulator_description/meshes/collada/shoulder_link.dae"/>
      </geometry>
      <material name="">
        <color rgba="0.7 0.2 0.4 1"/>
      </material>
    </visual>
    <collision>
      <origin rpy="0 0 0" xyz="0 0 0"/>
      <geometry>
        <mesh filename="package://jinu_manipulator_description/meshes/collada/shoulder_link.dae"/>
      </geometry>
    </collision>
    <inertial>
      <origin rpy="0 0 0" xyz="-0.00015946 0.02935 0.094506"/>
      <mass value="0.52932"/>
      <inertia ixx="0.000257" ixy="-5.943E-07" ixz="-1.8105E-07" iyy="0.00038939" iyz="-1.5019E-06" izz="0.00029988"/>
    </inertial>
  </link>
  <!--  Joint 2 -->
  <joint name="joint2" type="revolute">
    <parent link="link2"/>
    <child link="link3"/>
    <origin rpy="0 1.57 0" xyz="0.0 0.0 0.101"/>
    <axis xyz="0 1 0"/>
    <limit effort="1" lower="-1.5707963267948966" upper="1.5707963267948966" velocity="4.8"/>
  </joint>
  <!--  Link 3 -->
  <link name="link3">
    <visual>
      <origin rpy="0 0 0" xyz="0 0 0"/>
      <geometry>
        <mesh filename="package://jinu_manipulator_description/meshes/collada/arm_link.dae"/>
      </geometry>
      <material name="grey"/>
    </visual>
    <collision>
      <origin rpy="0 0 0" xyz="0 0 0"/>
      <geometry>
        <mesh filename="package://jinu_manipulator_description/meshes/collada/arm_link.dae"/>
      </geometry>
    </collision>
    <inertial>
      <origin rpy="0 0 0" xyz="-0.043569 -0.018054 0.00023288"/>
      <mass value="0.67459"/>
      <inertia ixx="0.00024014" ixy="-1.0253E-06" ixz="4.9927E-07" iyy="0.0018727" iyz="1.6438E-08" izz="0.0017182"/>
    </inertial>
  </link>
  <!--  Joint 3 -->
  <joint name="joint3" type="revolute">
    <parent link="link3"/>
    <child link="link4"/>
    <origin rpy="0 -1.57 0" xyz="-0.2495 0 0"/>
    <axis xyz="0 1 0"/>
    <limit effort="1" lower="-3.141592653589793" upper="0" velocity="4.8"/>
  </joint>
  <!--  Link 4 -->
  <link name="link4">
    <visual>
      <origin rpy="0 0 0" xyz="0 0 0"/>
      <geometry>
        <mesh filename="package://jinu_manipulator_description/meshes/collada/elbow_link.dae"/>
      </geometry>
      <material name="grey"/>
    </visual>
    <collision>
      <origin rpy="0 0 0" xyz="0 0 0"/>
      <geometry>
        <mesh filename="package://jinu_manipulator_description/meshes/collada/elbow_link.dae"/>
      </geometry>
    </collision>
    <inertial>
      <origin rpy="0 0 0" xyz="0.13512 -0.0014811 0.051429"/>
      <mass value="0.43335"/>
      <inertia ixx="0.00022562" ixy="3.1358E-07" ixz="-0.00026116" iyy="0.0013039" iyz="4.3754E-08" izz="0.0011013"/>
    </inertial>
  </link>
  <!--  Joint 4 -->
  <joint name="joint4" type="revolute">
    <parent link="link4"/>
    <child link="link5"/>
    <origin rpy="0 0 0" xyz="0.2388 0 0.074"/>
    <axis xyz="0 1 0"/>
    <limit effort="1" lower="-1.790707812546182" upper="1.790707812546182" velocity="4.8"/>
  </joint>
  <!--  Link 5 -->
  <link name="link5">
    <visual>
      <origin rpy="0 0 0" xyz="0 0 0"/>
      <geometry>
        <mesh filename="package://jinu_manipulator_description/meshes/collada/forearm_link.dae"/>
      </geometry>
      <material name="grey"/>
    </visual>
    <collision>
      <origin rpy="0 0 0" xyz="0 0 0"/>
      <geometry>
        <mesh filename="package://jinu_manipulator_description/meshes/collada/forearm_link.dae"/>
      </geometry>
    </collision>
    <inertial>
      <origin rpy="0 0 0" xyz="0.046587 0.00093527 4.9083E-06"/>
      <mass value="0.13384"/>
      <inertia ixx="3.6374E-05" ixy="1.1852E-06" ixz="4.7596E-10" iyy="2.2671E-05" iyz="-2.5504E-07" izz="2.207E-05"/>
    </inertial>
  </link>
  <!--  Joint 5 -->
  <joint name="joint5" type="revolute">
    <parent link="link5"/>
    <child link="link6"/>
    <origin rpy="0 0 0" xyz=" 0 0 0"/>
    <axis xyz="1 0 0"/>
    <limit effort="1" lower="-3.141592653589793" upper="3.141592653589793" velocity="4.8"/>
  </joint>
  <!--  Link 6 -->
  <link name="link6">
    <visual>
      <origin rpy="0 0 0" xyz="0 0 0"/>
      <geometry>
        <mesh filename="package://jinu_manipulator_description/meshes/collada/wrist_link.dae"/>
      </geometry>
      <material name="grey"/>
    </visual>
    <collision>
      <origin rpy="0 0 0" xyz="0 0 0"/>
      <geometry>
        <mesh filename="package://jinu_manipulator_description/meshes/collada/wrist_link.dae"/>
      </geometry>
    </collision>
    <inertial>
      <origin  rpy="0 0 0" xyz="0.093798 0.00012709 -0.0035622"/>
      <mass    value="0.11491" />
      <inertia ixx="1.8999E-05" ixy="2.1477E-07" ixz="1.819E-06"
               iyy="2.0277E-05" iyz="1.0553E-08"
               izz="3.2623E-05" />
    </inertial>
  </link>
  <!--  Joint 6 -->
  <joint name="joint6" type="revolute">
    <parent link="link6"/>
    <child link="link7"/>
    <origin rpy="0 0 0" xyz="0.0965 0 0"/>
    <axis xyz="0 0 1"/>
    <limit effort="1" lower="-3.141592653589793" upper="3.141592653589793" velocity="4.8"/>
  </joint>
  <!--  Link 7 -->
  <link name="link7">
    <visual>
      <origin rpy="0 0 0" xyz="0 0 0"/>
      <geometry>
        <mesh filename="package://jinu_manipulator_description/meshes/collada/endeff_link.dae"/>
      </geometry>
      <material name="grey"/>
    </visual>
    <collision>
      <origin rpy="0 0 0" xyz="0 0 0"/>
      <geometry>
        <mesh filename="package://jinu_manipulator_description/meshes/collada/endeff_link.dae"/>
      </geometry>
    </collision>
    <inertial>
      <origin rpy="0 0 0" xyz="0.048577 0.0005182 0.022163"/>
      <mass value="0.12395"/>
      <inertia ixx="7.2028E-05" ixy="4.5222E-08" ixz="8.2578E-07" iyy="2.6906E-05" iyz="1.8737E-07" izz="6.267E-05"/>
    </inertial>
  </link>
  <!-- Gripper Joint-->
  <joint name="gripper" type="prismatic">
    <origin rpy="0 0 0" xyz="0.0655 -0.053826 0"/>
    <parent link="link7"/>
    <child link="gripper_link"/>
    <axis xyz="0 1 0"/>
    <limit effort="0" lower="0" upper="0" velocity="0"/>
  </joint>
  <!-- Gripper link-->
  <link name="gripper_link">
    <inertial>
      <origin rpy="0 0 0" xyz="0.022425 -0.0013661 -0.00010039"/>
      <mass value="0.016158"/>
      <inertia ixx="1.7408E-06" ixy="-1.0523E-06" ixz="-1.1613E-10" iyy="6.2034E-06" iyz="-7.1721E-12" izz="7.2381E-06"/>
    </inertial>
    <visual>
      <origin rpy="0 0 0" xyz="0 0 0"/>
      <geometry>
        <mesh filename="package://jinu_manipulator_description/meshes/stl/gripper_link.stl"/>
      </geometry>
      <material name="">
        <color rgba="0.79216 0.81961 0.93333 1"/>
      </material>
    </visual>
    <collision>
      <origin rpy="0 0 0" xyz="0 0 0"/>
      <geometry>
        <mesh filename="package://jinu_manipulator_description/meshes/stl/gripper_link.stl"/>
      </geometry>
    </collision>
  </link>
  <!-- Gripper Joint sub-->
  <joint name="gripper_sub" type="prismatic">
    <origin rpy="0 0 0" xyz="0.0655 0.053826 0"/>
    <parent link="link7"/>
    <child link="gripper_link_sub"/>
    <axis xyz="0 -1 0"/>
    <limit effort="0" lower="0" upper="0" velocity="0"/>
  </joint>
  <!-- Gripper link sub-->
  <link name="gripper_link_sub">
    <inertial>
      <origin rpy="0 0 0" xyz="0.022425 0.0013661 -0.0001004"/>
      <mass value="0.016158"/>
      <inertia ixx="1.7408E-06" ixy="1.0523E-06" ixz="-1.1695E-10" iyy="6.2034E-06" iyz="6.5231E-12" izz="7.2381E-06"/>
    </inertial>
    <visual>
      <origin rpy="0 0 0" xyz="0 0 0"/>
      <geometry>
        <mesh filename="package://jinu_manipulator_description/meshes/stl/gripper_sub_link.stl"/>
      </geometry>
      <material name="">
        <color rgba="0.79216 0.81961 0.93333 1"/>
      </material>
    </visual>
    <collision>
      <origin rpy="0 0 0" xyz="0 0 0"/>
      <geometry>
        <mesh filename="package://jinu_manipulator_description/meshes/stl/gripper_sub_link.stl"/>
      </geometry>
    </collision>
  </link>
  <!-- Realsense Camera Joint Position -->
  <!--   <joint name="camera_joint" type="fixed">
    <axis xyz="0 1 0" />
    <origin xyz="0.070 0.032 0.052" rpy="0 0 0"/> 
    <parent link="link5"/>
    <child link="camera_link"/>
  </joint>

  <link name="camera_link"/> -->
</robot>

