<?xml version="1.0" encoding="utf-8"?>
<!-- This URDF was automatically created by SolidWorks to URDF Exporter! Originally created by Stephen Brawner (brawner@gmail.com) 
     Commit Version: 1.6.0-4-g7f85cfe  Build Version: 1.6.7995.38578
     For more information, please see http://wiki.ros.org/sw_urdf_exporter -->
<robot name="jinumanip">
  <!-- Properties -->
  <!-- Links -->
  <link name="world"/>

  <link name="base_link">    
    <visual>
      <origin xyz="0 0 0" rpy="0 0 0" />
      <geometry>
        <mesh filename="package://jinumanip/meshes/base_link.dae" />
      </geometry>
      <material name="">
        <color rgba="0.698039215686274 0.698039215686274 0.698039215686274 1" />
      </material>
    </visual>
    <collision>
      <origin xyz="0 0 0" rpy="0 0 0" />
      <geometry>
        <mesh filename="package://jinu_manipulator_description/meshes/collada/base_link.dae" />
      </geometry>
    </collision>
  </link>

  <link name="Link1">
    <visual>
      <origin
        xyz="0 0 0"
        rpy="0 0 0" />
      <geometry>
        <mesh
          filename="package://jinumanip/meshes/shoulder_link.dae" />
      </geometry>
      <material
        name="">
        <color
          rgba="0.698039215686274 0.698039215686274 0.698039215686274 1" />
      </material>
    </visual>
    <collision>
      <origin
        xyz="0 0 0"
        rpy="0 0 0" />
      <geometry>
        <mesh
          filename="package://jinumanip/collada/shoulder_link.dae" />
      </geometry>
    </collision>
  </link>

  <link name="Link2">
    <visual>
      <origin
        xyz="0 0 0"
        rpy="0 0 0" />
      <geometry>
        <mesh
          filename="package://jinumanip/meshes/Link2.STL" />
      </geometry>
      <material
        name="">
        <color
          rgba="0.898039215686275 0.917647058823529 0.929411764705882 1" />
      </material>
    </visual>
    <collision>
      <origin
        xyz="0 0 0"
        rpy="0 0 0" />
      <geometry>
        <mesh
          filename="package://jinumanip/meshes/Link2.STL" />
      </geometry>
    </collision>
  </link>

  <link name="Link3">
    <visual>
      <origin
        xyz="0 0 0"
        rpy="0 0 0" />
      <geometry>
        <mesh
          filename="package://jinumanip/meshes/Link3.STL" />
      </geometry>
      <material
        name="">
        <color
          rgba="0.698039215686274 0.698039215686274 0.698039215686274 1" />
      </material>
    </visual>
    <collision>
      <origin
        xyz="0 0 0"
        rpy="0 0 0" />
      <geometry>
        <mesh
          filename="package://jinumanip/meshes/Link3.STL" />
      </geometry>
    </collision>
  </link>

  <link name="Link4">
    <visual>
      <origin
        xyz="0 0 0"
        rpy="0 0 0" />
      <geometry>
        <mesh
          filename="package://jinumanip/meshes/Link4.STL" />
      </geometry>
      <material
        name="">
        <color
          rgba="0.501960784313725 0.501960784313725 1 1" />
      </material>
    </visual>
    <collision>
      <origin
        xyz="0 0 0"
        rpy="0 0 0" />
      <geometry>
        <mesh
          filename="package://jinumanip/meshes/Link4.STL" />
      </geometry>
    </collision>
  </link>

  <link name="Link5">
    <visual>
      <origin
        xyz="0 0 0"
        rpy="0 0 0" />
      <geometry>
        <mesh
          filename="package://jinumanip/meshes/Link5.STL" />
      </geometry>
      <material
        name="">
        <color
          rgba="0.501960784313725 1 0.501960784313725 1" />
      </material>
    </visual>
    <collision>
      <origin
        xyz="0 0 0"
        rpy="0 0 0" />
      <geometry>
        <mesh
          filename="package://jinumanip/meshes/Link5.STL" />
      </geometry>
    </collision>
  </link>

  <link name="Link6">
    <visual>
      <origin
        xyz="0 0 0"
        rpy="0 0 0" />
      <geometry>
        <mesh
          filename="package://jinumanip/meshes/Link6.STL" />
      </geometry>
      <material
        name="">
        <color
          rgba="1 0.501960784313725 1 1" />
      </material>
    </visual>
    <collision>
      <origin
        xyz="0 0 0"
        rpy="0 0 0" />
      <geometry>
        <mesh
          filename="package://jinumanip/meshes/Link6.STL" />
      </geometry>
    </collision>
  </link>

  <joint name="yaw_joint" type="continuous">
    <origin xyz="0 0 0" rpy="0 0 0" />
    <parent link="base_joint" />
    <child link="Link1" />
    <axis xyz="0 0 -1" />
  </joint>  

  <joint name="sholder_joint" type="continuous">
    <origin xyz="0 0 0.1010000104904" rpy="0 0 0" />
    <parent link="Link1" />
    <child link="Link2" />
    <axis xyz="0 1 0" />
  </joint>
  
  <joint name="elbow_joint" type="continuous">
    <origin xyz="-0.2495 0 0" rpy="0 0 0" />
    <parent link="Link2" />
    <child  link="Link3" />
    <axis xyz="0 1 0" />
  </joint>
  
  <joint name="wrist_joint" type="continuous">
    <origin xyz="0.238796984905589 0 0.0739999999999999" rpy="0 0 0" />
    <parent link="Link3" />
    <child link="Link4" />
    <axis xyz="0 -1 0" />
  </joint>
  
  <joint name="wrist2_joint" type="continuous">
    <origin xyz="0 0 0" rpy="0 0 0" />
    <parent link="Link4" />
    <child link="Link5" />
    <axis xyz="-1 0 0" />
  </joint>
  
  <joint name="joint_ee"
    type="fixed">
    <origin
      xyz="0.0965000000000001 0 0"
      rpy="0 0 0" />
    <parent
      link="Link5" />
    <child
      link="Link6" />
    <axis
      xyz="0 0 0" />
  </joint>

</robot>
